Workbook
Name 문서명: #REF!
Name 문서명: #REF!
Name 문서명: #REF!
Name 문서명: #REF!
Name 문서명: #REF!
Name 문서번호: #REF!
Name 문서번호: #REF!
Name 문서번호: #REF!
Name 문서번호: #REF!
Name 문서번호: #REF!
Name 프로젝트명: #REF!
Name 프로젝트명: #REF!
Name 프로젝트명: #REF!
Name 프로젝트명: #REF!
Name 프로젝트명: #REF!

Sheet 추적 테스트시나리오목록
A1: No. | B1: 시스템명 | C1: 업무명 | D1: 시나리오명 | E1: 계획 시작일 | F1: 계획 완료일 | G1: 실제 시작일 | H1: 실제 완료일 | I1: 테스트 수 | J1: 통계 | P1: 비고(특이사항)
J2: Pass 수 | K2: Fail 수 | L2: N/A | M2: 조치 수 | N2: 조치율 | O2: 최종결과 (P:Pass, F:Fail)
I3: =SUM(I4:I37) -> 124 | J3: =SUM(J4:J37) -> 0 | K3: =SUM(K4:K37) -> 0 | L3: =SUM(L4:L37) -> 0 | M3: =SUM(M4:M37) -> 0 | N3: =IFERROR(M3/K3,"-") -> -
A4: 1 | B4: 물류네트워크 | C4: Digital Cargo-Tracking ( C) | D4: 해상수입 | E4: 44790 | F4: 44790 | I4: =해상수입!$J$3 -> 31 | J4: =해상수입!$K$3 -> 0 | K4: =해상수입!$L$3 -> 0 | L4: =해상수입!$M$3 -> 0 | M4: =해상수입!$N$3 -> 0 | N4: =해상수입!$O$3 -> -
A5: 2 | B5: 물류네트워크 | C5: Digital Cargo-Tracking ( C) | D5: 해상수출 | E5: 44790 | F5: 44790 | I5: =해상수출!$J$3 -> 31 | J5: =해상수출!$K$3 -> 0 | K5: =해상수출!$L$3 -> 0 | L5: =해상수출!$M$3 -> 0 | M5: =해상수출!$N$3 -> 0 | N5: =해상수출!$O$3 -> -
A6: 3 | B6: 물류네트워크 | C6: Digital Cargo-Tracking ( C) | D6: 항공수입 | E6: 44790 | F6: 44790 | I6: =항공수입!$J$3 -> 31 | J6: =항공수입!$K$3 -> 0 | K6: =항공수입!$L$3 -> 0 | L6: =항공수입!$M$3 -> 0 | M6: =항공수입!$N$3 -> 0 | N6: =항공수입!$O$3 -> -
A7: 4 | B7: 물류네트워크 | C7: Digital Cargo-Tracking ( C) | D7: 항공수출 | E7: 44790 | F7: 44790 | I7: =해상수입!$J$3 -> 31 | J7: =항공수출!$K$3 -> 0 | K7: =항공수출!$L$3 -> 0 | L7: =항공수출!$M$3 -> 0 | M7: =항공수출!$N$3 -> 0 | N7: =항공수출!$O$3 -> -

Sheet 추적필수정보
A1: 추적 모니터링을 위한 수출입/운송 업무화면 정보(최소값)
A3: 수출입 | B3: 해상수출 | C3: 해상수입 | D3: 항공수출 | E3: 항공수입
B4: B/L등록 | C4: B/L등록 | D4: B/L등록 | E4: B/L등록
B5: 부킹번호 | C5: 부킹번호 | D5: 부킹번호 | E5: B/L관리번호
B6: B/L관리번호 | C6: B/L관리번호 | D6: B/L관리번호 | E6: 하우스AWB번호
B7: 하우스BL번호 | C7: 하우스BL번호 | D7: 하우스AWB번호 | E7: 마스터AWB번호
B8: 선적항코드 | C8: 마스터BL번호
B9: 선적항명 | C9: 선적항코드
B10: 선적항출발예상시간 | C10: 선적항명
B11: 양허항코드 | C11: 선적항출발예상시간
B12: 양허항명 | C12: 양허항코드
B13: 양하항입항예상시간 | C13: 양허항명
C14: 양하항입항예상시간
A16: 운송 | B16: 배차등록
B17: 운송오더관리(수출) | C17: 운송오더관리(수입)
B18: 운송오더관리번호 | C18: 운송오더관리번호
B19: 부킹번호 | C19: 하우스BL번호
B20: 출발지코드 | C20: 출발지코드
B21: 출발지명 | C21: 출발지명
B22: 운송시작일자시간 | C22: 운송시작일자시간
B23: 도착지코드 | C23: 도착지코드
B24: 도착지명 | C24: 도착지명
B25: 운송종료일자시간 | C25: 운송종료일자시간
B26: 차량번호 | C26: 차량번호
B27: 운전자명 | C27: 운전자명
B28: 운전자모바일번호 | C28: 운전자모바일번호
B29: 컨테이너번호 | C29: 컨테이너번호

Sheet Data(해상수입)
A1: Data(해상수입)
A3: CASE 1 | B3: 항목명 | C3: 항목설명 | D3: 값 | E3: 기타
B4: BL TYPE | D4: SIMPLE
B5: M B/L NO | D5: SMLMVAN2A0923400
B6: 화물관리번호 | D6: 22SMLM0114I-0002
B7: POD | C7: 양하항 | D7: KRBNP | E7: 항구(부산신항)
B8: POL | C8: 선적항 | D8: CAVAN | E8: 항구(캐나다, 벤쿠버)
B9: 운항정보
B10: MRN | C10: 화물관리번호 | D10: 22SMLM0114I
B11: VESSEL NAM | C11: 선명 | D11: KOTA LUKIS
B12: CALLSIGN | C12: 호출부호 | D12: VRSN8
B13: VOYAGE NO | C13: 항차 | D13: 2202W
B14: ETA | C14: 도착예정시간 | D14: 20220731
B15: 경유항 | D15: (ETD/ETA) | E15: (출발예정시간,도착예정시간)
C16: USSEA | D16: 2022-07-12 06:00 2022-07-13 04:00 | E16: 항구(미국, 시에틀)
C17: CAVAN | D17: 2022-07-15 00:01 2022-07-16 18:57 | E17: 항구(캐나다, 벤쿠버)
C18: USPDX | D18: 2022-07-17 14:42 2022-07-19 19:00 | E18: 항구(미국, 포틀랜드)
C19: KRPUS | E19: 항구(부산)
B20: 컨테이너 정보 | D20: FCIU2624665 | E20: 22GP, 봉인번호 : 103804
D21: SDCU2368442 | E21: 22GP, 봉인번호 : 103819
D22: SMCU2003150 | E22: 22GP, 봉인번호 : 103801
D23: SMCU2019114 | E23: 22GP, 봉인번호 : 103805
D24: SMCU2030495 | E24: 22GP, 봉인번호 : 103802
D25: SMCU2035352 | E25: 22GP, 봉인번호 : 103813
B26: 화물통관진행정보 (관세청 API) | D26: 22SMLM0114I-0002
A28: CASE 2 | B28: 항목명 | C28: 항목설명 | D28: 값 | E28: 기타
B29: BL TYPE | D29: CONSOL FCL
B30: 포워더 코드 | D30: MAXP
B31: 선사코드 | D31: HDMU
B32: M B/L NO | D32: HDMUCGPA64044900
B33: 화물관리번호
B34: POD | C34: 양하항 | D34: KRBNP | E34: 항구(부산신항)
B35: POL | C35: 선적항 | D35: BDCGP | E35: 항구(방글라데시, 시타공)
B36: PLD | C36: 도착지 | D36: KRPUS | E36: 항구(부산)
B37: 운항정보
B38: MRN | C38: 화물관리번호 | D38: 22HDMUA367I
B39: VESSEL NAM | C39: 선명 | D39: HYUNDAI HONGKONG
B40: CALLSIGN | C40: 호출부호 | D40: 5BZL3
B41: VOYAGE NO | C41: 항차 | D41: 0136E
B42: ETA | C42: 도착예정시간 | D42: 20220714
...

Sheet Data(해상수출)
A1: Data(해상수출)
A3: CASE 1 | B3: 항목명 | C3: 항목설명 | D3: 값 | E3: 기타
B4: BL TYPE | D4: SIMPLE
B5: 선사코드 | D5: SMLM | E5: *포워더 및 화주가 등록시
B6: M B/L NO | D6: SMLMSEL2J1252700
B7: POL | C7: 선적항 | D7: KRPUS | E7: 항구(부산)
B8: POD | C8: 양하항 | D8: VNHPH | E8: 항구(베트남,하이퐁)
B9: PLD | C9: 도착지 | D9: VNHPH | E9: 항구(베트남,하이퐁)
B10: M 부킹번호 | D10: SEL2J1252700
B11: H B/L NO | D11: SEL2J1252700 | E11: *SIMPLE 인 경우 M B/L 과 동일 처리
B12: 컨테이너 정보 | D12: BMOU2745329 | E12: 22GP, 봉인번호 : SM503583
D13: CAIU6601490 | E13: 22GP, 봉인번호 : SM516803
B14: 수출신고번호별 수출이행내역 | D14: 4344622400947X
B15: 운항정보
B16: MRN | C16: 화물관리번호 | D16: 22SMLME107E
B17: VESSEL NAM | C17: 선명 | D17: SM TOKYO
B18: CALLSIGN | C18: 호출부호 | D18: D7DO
B19: VOYAGE NO | C19: 항차 | D19: 2213W
B20: ETD | C20: 출항일시 | D20: 20220803 00:00
B21: 경유항 | D21: (ETD/ETA) | E21: (출발예정시간,도착예정시간)
C22: KRPUS | E22: 항구(부산)
C23: VNHP | D23: 2022-08-07-19:00 2022-08-08-12:30 | E23: 항구(베트남,하이퐁)
C24: CNXMN | D24: 2022-08-10-13:00 2022-08-11-03:30 | E24: 항구(중국,샤먼)
C25: KRINC | D25: 2022-08-11-07:00 2022-08-11-17:00 | E25: 항구(인천)
C26: KRKAN | D26: 2022-08-12-18:30 2022-08-13-06:00 | E26: 항구(광양)
A28: CASE 2 | B28: 항목명 | C28: 항목설명 | D28: 값 | E28: 기타
B29: BL TYPE | D29: CONSOL, FCL
B30: 포워더 | D30: ANBG
B31: 선사코드 | D31: ONEY | E31: *포워더 및 화주가 등록시
B32: M B/L NO | D32: ONEYSELCA1341900
B33: POL | C33: 선적항 | D33: KRPUS | E33: 항구(부산)
B34: POD | C34: 양하항 | D34: VNHPH | E34: 항구(베트남,하이퐁)
B35: PLD | C35: 도착지 | D35: VNHPH | E35: 항구(베트남,하이퐁)
B36: M 부킹번호 | D36: SELCA1341900
B37: H B/L NO | D37: ANBHPH22080051
B38: 수출신고번호별 수출이행내역 | D38: 4161922703596X
B39: 컨테이너 정보 | D39: TCKU3371860 | E39: 22GP, 봉인번호 : KRAM07745
D40: TCLU3425516 | E40: 22GP, 봉인번호 : KRAM02375
D41: TGBU3251999 | E41: 22GP, 봉인번호 : KRAM02320
B42: 운항정보
...

Sheet 해상수입
A1: 시나리오명 | B1: 해상 수입 | F1: 시나리오 설명 | H1: 1) 해상 수입 업무 실데이터를 통한 화물추적 모니터링 테스트
A2: 업무흐름 | B2: 1) 해상 수입 업부에 따른 실 데이터를 입력하고 화물추적 모니터링화면에서 화물위치/화물추적/운송자산별로 데이터 추적을 진행한다. | F2: 테스트 결과 | H2: 구분 | I2: 테스트일자 | J2: 테스트 수 | K2: Pass 수 | L2: Fail 수 | M2: N/A | N2: 조치 수 | O2: 조치율 | P2: 테스트결과
H3: 통계 | I3: 44790 | J3: =COUNTA($F$6:$F$205) -> 31 | K3: =COUNTIF($J$6:$J$205,"P") -> 0 | L3: =COUNTIF($J$6:$J$205,"F") -> 0 | M3: =COUNTIF($J$6:$J$205,"N/A") -> 0 | N3: =COUNTA($O$6:$O$205) -> 0 | O3: =IFERROR(N3/L3,"-") -> - | P3: P
A4: 통합테스트 시나리오 | E4: 통합테스트 케이스 | J4: 테스트결과 | M4: 조치결과
A5: 사용자 | B5: 메뉴 | D5: 단위기능(화면 명) | E5: ID | F5: 테스트 케이스 | G5: 테스트 데이터 | H5: 예상결과 | I5: 사전조건 | J5: 테스트 결과 | K5: 결함내용/비고 | M5: 조치자 | N5: 조치예정일 | O5: 조치완료일 | P5: 조치내용/비고
A6: 무역업체(포워더) | B6: Shipping>수입B/L관리>해상B/L조회 | D6: 해상B/L조회 | E6: 01 | F6: [등록] 목록 화면에서 '신규'버튼 클릭. | H6: B/L등록 화면으로 이동 | I6: ID : FSARIR0001 (아리랑 국제물류)
D7: 해상B/L조회 (Main TAB) | E7: 02 | F7: [등록] MAIN TAB 정보 등록 | G7: 수출입구분 업무유형 M BL NO H BL NO SHIPPIER CONSIGNEE NOTIFY LINE CALL SIGN PORT OF LOADING PORT OF DISCHARGE FINAL DESTINATION VESSEL NAME VOYAGE NO ONBOARD DATE ETD / ETA | I7: 수출입구분 (수입) 업무유형(CONSOL)
D8: 해상B/L조회 (Cargo TAB) | E8: 03 | F8: [등록] CARGO TAB 정보 등록 | G8: 컨테이너 규격(유형) Package Gross Weight Measurerment R.Ton Container 20 Container 40 Container No Container 규격 Seal No 1 Package Unit G.Weight Measurement | I8: 컨테이너 규격(유형) Ex) (LCL/FCL/BULK) Container 20(갯수입력) Container 40(갯수입력)
D9: 해상B/L조회 (Other TAB) | E9: 04 | F9: [등록] OTHER TAB 정보 등록 | G9: MRN NO MSN HSN
E10: 05 | F10: [등록] TAB 정보를 등록 완료후 '저장'버튼 클릭. | H10: 목록화면으로 이동, 저장된 B/L등록건의 정보를 목록에서 표시 처리
A11: 무역업체(포워더) | B11: Cargo Tracking>My Cargo-Tracking>실시간모니터링 | D11: 화물위치 (Tab) | E11: 06 | F11: [검색조건] 조회일자 : [시작일]~[종료일] 조회 | H11: 조건에 따른 목록 조회 | I11: ID : FSARIR0001 (아리랑 국제물류)
E12: 07 | F12: [검색조건] 조회일자 : [2주] 버튼 조회 | H12: 조건에 따른 목록 조회
E13: 08 | F13: [검색조건] 조회일자 : [1달] 버튼 조회 | H13: 조건에 따른 목록 조회
E14: 09 | F14: [검색조건] 조회일자 : [2달] 버튼 조회 | H14: 조건에 따른 목록 조회
E15: 10 | F15: [검색조건] 수 · 출입 : 수입 선택 후 검색조건별 조회 | H15: 조건에 따른 목록 조회
E16: 11 | F16: 목록 선택하여 지도에 운송체 아이콘 표출 | H16: 지도에 아이콘 표시
E17: 12 | F17: 지도의 운송체 아이콘 선택하여 팝업 노출 | H17: -운송체 정보 노출 -출발지~도착지 정보 노출 -최종 정보 수집일시 정보 노출 -[상세정보] 버튼 선택하여 운송체 세부 정보 노출 -[TRACKING] 버튼 선택하여 [화물추적 (Tab)]으로 이동
E18: 13 | F18: 검색된 목록의 [화물추적] 버튼 선택 | H18: [화물추적 (Tab)]으로 이동
D19: 화물추적 (Tab) | E19: 14 | F19: (수 · 출입 : 수입이 선택되어 있음) 선사/포워더 : 수동 입력 후 조회 | H19: 조건에 따른 목록 조회
E20: 15 | F20: [검색조건] 선사/포워더 : [LIST] 버튼 조회 | H20: 선사/포워더 조회 팝업 노출
E21: 16 | F21: [선사/포워더 팝업창] 조회 -코드값 입력하여 조회 -조회된 목록 선택하여 검색옵션에 자동입력 | H21: 조건에 따른 목록 조회
E22: 17 | F22: [검색조건] 검색조건 : [LIST] 버튼 조회 (BL조회) | H22: B/L 조회 팝업 노출
E23: 18 | F23: [B/L 조회 팝업창] 조회 -조회일자 : 시작일~종료일 선택 조회 -[2주] 버튼 조회 -[1달] 버튼 조회 -[2달] 버튼 조회 -수 · 출입 옵션 선택 후 검색조건 선택 조회 -B/L 입력하여 조회 -조회된 목록 선택하여 검색옵션에 자동입력 | H23: 조건에 따른 목록 조회
E24: 19 | F24: [Event Tracking] -선박운송 | H24: 기항지별 출발/도착 시간 노출
E25: 20 | F25: [Event Tracking] -항공기운송 | H25: 출발/도착 시간 노출
E26: 21 | F26: [Event Tracking] -내륙운송(컨테이너) | H26: 컨테이너 번호 노출 -이벤트(출발(반출), 상차, 하차)별 시간 노출
E27: 22 | F27: [Event Tracking] -내육운송(화물) | H27: 이벤트(출발,하차)별 시간 노출
E28: 23 | F28: [Document Tracking] -DOCUMENT | H28: 수출입서류별 B/L 시간 노출
E29: 24 | F29: [Document Tracking] -수입화물진행정보 | H29: 세관서류별 시간 노출
D30: 운송자산 (Tab) | E30: 25 | F30: [검색조건] -운송유형, 운송상태, 검색조건 조회 | H30: 조건에 따른 목록 조회
E31: 26 | F31: [선박등록(직접) 팝업창]조회 -선박 조회 -신규 등록 | H31: -조건에 따른 목록 조회 -신규선박 등록
E32: 27 | F32: [입출항 팝업창]조회 -조회 -조회결과에서 체크하여 등록 | H32: -조건에 따른 목록 조회 -즐겨찾기 등록
E33: 28 | F33: 목록 선택하여 지도에 운송체 아이콘 표출 | H33: 지도에 아이콘 표시
E34: 29 | F34: 지도의 자산 아이콘 선택하여 팝업 노출 | H34: -항적 정보 노출 -[상세정보] 버튼 선택하여 운송체 세부 정보 노출
E35: 30 | F35: [운송자산 팝업창]의 [알람설정] -[알람설정] 버튼 선택하여 팝업창 노출 -알람설정 등록 | H35: -알람설정 등록 -조건에 따른 알람 발송
E36: 31 | F36: [운송자산 팝업창]의 [터미널정보] -[터미널정보] 버튼 선택하여 팝업창 노출 | H36: -터미널 정보 노출 -[하선장소] 선택하여 주소로 팝업창(지도) 노출 -본선작업현황 노출

Sheet 해상수출
A1: 시나리오명 | B1: 해상 수출 | F1: 시나리오 설명 | H1: 1) 해상 수출 업무 실데이터를 통한 화물추적 모니터링 테스트
A2: 업무흐름 | B2: 1) 해상 수출 업부에 따른 실 데이터를 입력하고 화물추적 모니터링화면에서 화물위치/화물추적/운송자산별로 데이터 추적을 진행한다. | F2: 테스트 결과 | H2: 구분 | I2: 테스트일자 | J2: 테스트 수 | K2: Pass 수 | L2: Fail 수 | M2: N/A | N2: 조치 수 | O2: 조치율 | P2: 테스트결과
H3: 통계 | I3: 44790 | J3: =COUNTA($F$6:$F$205) -> 31 | K3: =COUNTIF($J$6:$J$205,"P") -> 0 | L3: =COUNTIF($J$6:$J$205,"F") -> 0 | M3: =COUNTIF($J$6:$J$205,"N/A") -> 0 | N3: =COUNTA($O$6:$O$205) -> 0 | O3: =IFERROR(N3/L3,"-") -> - | P3: P
A4: 통합테스트 시나리오 | E4: 통합테스트 케이스 | J4: 테스트결과 | M4: 조치결과
A5: 사용자 | B5: 메뉴 | D5: 단위기능(화면 명) | E5: ID | F5: 테스트 케이스 | G5: 테스트 데이터 | H5: 예상결과 | I5: 사전조건 | J5: 테스트 결과 | K5: 결함내용/비고 | M5: 조치자 | N5: 조치예정일 | O5: 조치완료일 | P5: 조치내용/비고
A6: 무역업체(포워더) | B6: Shipping>수출B/L관리>해상B/L조회 | D6: 해상B/L조회 | E6: 01 | F6: [등록] 목록 화면에서 '신규'버튼 클릭. | H6: B/L등록 화면으로 이동 | I6: ID : FSARIR0001 (아리랑 국제물류)
D7: 해상B/L조회 (Main TAB) | E7: 02 | F7: [등록] MAIN TAB 정보 등록 | G7: 수출입구분(수출) 업무유형 M BL NO H BL NO SHIPPIER CONSIGNEE NOTIFY LINE CALL SIGN PORT OF LOADING PORT OF DISCHARGE FINAL DESTINATION VESSEL NAME VOYAGE NO ONBOARD DATE ETD / ETA | I7: 수출입구분 (수출) 업무유형(CONSOL)
D8: 해상B/L조회 (Cargo TAB) | E8: 03 | F8: [등록] CARGO TAB 정보 등록 | G8: 컨테이너 규격(유형) (LCL/FCL/BULK) Package Gross Weight Measurerment R.Ton Container 20(갯수입력) Container 40(갯수입력) Container No Container 규격 Seal No 1 Package Unit G.Weight Measurement | I8: 컨테이너 규격(유형) Ex) (LCL/FCL/BULK) Container 20(갯수입력) Container 40(갯수입력)
D9: 해상B/L조회 (Other TAB) | E9: 04 | F9: [등록] OTHER TAB 정보 등록 | G9: MRN NO MSN HSN
E10: 05 | F10: [등록] TAB 정보를 등록 완료후 '저장'버튼 클릭. | H10: 목록화면으로 이동, 저장된 B/L등록건의 정보를 목록에서 표시 처리
A11: 무역업체(포워더) | B11: Cargo Tracking>My Cargo-Tracking>실시간모니터링 | D11: 화물위치 (Tab) | E11: 06 | F11: [검색조건] 조회일자 : [시작일]~[종료일] 조회 | H11: 조건에 따른 목록 조회 | I11: ID : FSARIR0001 (아리랑 국제물류)
E12: 07 | F12: [검색조건] 조회일자 : [2주] 버튼 조회 | H12: 조건에 따른 목록 조회
E13: 08 | F13: [검색조건] 조회일자 : [1달] 버튼 조회 | H13: 조건에 따른 목록 조회
E14: 09 | F14: [검색조건] 조회일자 : [2달] 버튼 조회 | H14: 조건에 따른 목록 조회
E15: 10 | F15: [검색조건] 수 · 출입 : 수출 선택 후 검색조건별 조회 | H15: 조건에 따른 목록 조회
E16: 11 | F16: 목록 선택하여 지도에 운송체 아이콘 표출 | H16: 지도에 아이콘 표시
E17: 12 | F17: 지도의 운송체 아이콘 선택하여 팝업 노출 | H17: -운송체 정보 노출 -출발지~도착지 정보 노출 -최종 정보 수집일시 정보 노출 -[상세정보] 버튼 선택하여 운송체 세부 정보 노출 -[TRACKING] 버튼 선택하여 [화물추적 (Tab)]으로 이동
E18: 13 | F18: 검색된 목록의 [화물추적] 버튼 선택 | H18: [화물추적 (Tab)]으로 이동
D19: 화물추적 (Tab) | E19: 14 | F19: (수 · 출입 : 수출이 선택되어 있음) 선사/포워더 : 수동 입력 후 조회 | H19: 조건에 따른 목록 조회
E20: 15 | F20: [검색조건] 선사/포워더 : [LIST] 버튼 조회 | H20: 선사/포워더 조회 팝업 노출
E21: 16 | F21: [선사/포워더 팝업창] 조회 -코드값 입력하여 조회 -조회된 목록 선택하여 검색옵션에 자동입력 | H21: 조건에 따른 목록 조회
E22: 17 | F22: [검색조건] 검색조건 : [LIST] 버튼 조회 (BL조회) | H22: B/L 조회 팝업 노출
E23: 18 | F23: [B/L 조회 팝업창] 조회 -조회일자 : 시작일~종료일 선택 조회 -[2주] 버튼 조회 -[1달] 버튼 조회 -[2달] 버튼 조회 -수 · 출입 옵션 선택 후 검색조건 선택 조회 -B/L 입력하여 조회 -조회된 목록 선택하여 검색옵션에 자동입력 | H23: 조건에 따른 목록 조회
E24: 19 | F24: [Event Tracking] -선박운송 | H24: 기항지별 출발/도착 시간 노출
E25: 20 | F25: [Event Tracking] -항공기운송 | H25: 출발/도착 시간 노출
E26: 21 | F26: [Event Tracking] -내륙운송(컨테이너) | H26: 컨테이너 번호 노출 -이벤트(출발(반출), 상차, 하차)별 시간 노출
E27: 22 | F27: [Event Tracking] -내육운송(화물) | H27: 이벤트(출발,하차)별 시간 노출
E28: 23 | F28: [Document Tracking] -DOCUMENT | H28: 수출입서류별 B/L 시간 노출
E29: 24 | F29: [Document Tracking] -수출화물진행정보 | H29: 세관서류별 시간 노출
D30: 운송자산 (Tab) | E30: 25 | F30: [검색조건] -운송유형, 운송상태, 검색조건 조회 | H30: 조건에 따른 목록 조회
E31: 26 | F31: [선박등록(직접) 팝업창]조회 -선박 조회 -신규 등록 | H31: -조건에 따른 목록 조회 -신규선박 등록
E32: 27 | F32: [입출항 팝업창]조회 -조회 -조회결과에서 체크하여 등록 | H32: -조건에 따른 목록 조회 -즐겨찾기 등록
E33: 28 | F33: 목록 선택하여 지도에 운송체 아이콘 표출 | H33: 지도에 아이콘 표시
E34: 29 | F34: 지도의 자산 아이콘 선택하여 팝업 노출 | H34: -항적 정보 노출 -[상세정보] 버튼 선택하여 운송체 세부 정보 노출
E35: 30 | F35: [운송자산 팝업창]의 [알람설정] -[알람설정] 버튼 선택하여 팝업창 노출 -알람설정 등록 | H35: -알람설정 등록 -조건에 따른 알람 발송
E36: 31 | F36: [운송자산 팝업창]의 [터미널정보] -[터미널정보] 버튼 선택하여 팝업창 노출 | H36: -터미널 정보 노출 -[하선장소] 선택하여 주소로 팝업창(지도) 노출 -선석배정현황 노출

Sheet 항공수입
A1: 시나리오명 | B1: 항공 수입 | F1: 시나리오 설명 | H1: 1) 항공 수입 업무 실데이터를 통한 화물추적 모니터링 테스트
A2: 업무흐름 | B2: 1) 항공 수입 업부에 따른 실 데이터를 입력하고 화물추적 모니터링화면에서 화물위치/화물추적/운송자산별로 데이터 추적을 진행한다. | F2: 테스트 결과 | H2: 구분 | I2: 테스트일자 | J2: 테스트 수 | K2: Pass 수 | L2: Fail 수 | M2: N/A | N2: 조치 수 | O2: 조치율 | P2: 테스트결과
H3: 통계 | I3: 44790 | J3: =COUNTA($F$6:$F$205) -> 31 | K3: =COUNTIF($J$6:$J$205,"P") -> 0 | L3: =COUNTIF($J$6:$J$205,"F") -> 0 | M3: =COUNTIF($J$6:$J$205,"N/A") -> 0 | N3: =COUNTA($O$6:$O$205) -> 0 | O3: =IFERROR(N3/L3,"-") -> - | P3: P
A4: 통합테스트 시나리오 | E4: 통합테스트 케이스 | J4: 테스트결과 | M4: 조치결과
A5: 사용자 | B5: 메뉴 | D5: 단위기능(화면 명) | E5: ID | F5: 테스트 케이스 | G5: 테스트 데이터 | H5: 예상결과 | I5: 사전조건 | J5: 테스트 결과 | K5: 결함내용/비고 | M5: 조치자 | N5: 조치예정일 | O5: 조치완료일 | P5: 조치내용/비고
A6: 무역업체(포워더) | B6: Shipping>수입B/L관리>항공AWB조회 | D6: 항공AWB조회 | E6: 01 | F6: [등록] 목록 화면에서 '신규'버튼 클릭. | H6: AWB등록 화면으로 이동 | I6: ID : FFRICS0001 (린코)
D7: 항공AWB조회 (Main TAB) | E7: 02 | F7: [등록] MAIN TAB 정보 등록 | G7: 수출입구분 업무유형 M AWB NO H AWB NO SHIPPIER CONSIGNEE NOTIFY AIR PORT OF DEPARTURE AIR PORT OF ARRIVAL TO / BY FLIGHT NO REQUEST NO DEPARTURE DATE ARRIVAL DATE REQUEST DATE | I7: 수출입구분 (수입) 업무유형(CONSOL) TO (출발공항코드) Ex) ICN BY (항공사 2 코드) Ex) OZ, KE
D8: 항공AWB조회 (Cargo TAB) | E8: 03 | F8: [등록] CARGO TAB 정보 등록 | G8: No of Piecces 포장종류 Gross Weight Exceuted on(Date) At(Place) | I8: Exceuted on(Date) (AWB 발행일자) At(Place) (AWB 발행장소)
D9: 항공AWB조회 (Other TAB) | E9: 04 | F9: [등록] OTHER TAB 정보 등록 | G9: MRN NO MSN HSN
E10: 05 | F10: [등록] TAB 정보를 등록 완료후 '저장'버튼 클릭. | H10: 목록화면으로 이동, 저장된 AWB등록건의 정보를 목록에서 표시 처리
A11: 무역업체(포워더) | B11: Cargo Tracking>My Cargo-Tracking>실시간모니터링 | D11: 화물위치 (Tab) | E11: 06 | F11: [검색조건] 조회일자 : [시작일]~[종료일] 조회 | H11: 조건에 따른 목록 조회 | I11: ID : FSARIR0001 (아리랑 국제물류)
E12: 07 | F12: [검색조건] 조회일자 : [2주] 버튼 조회 | H12: 조건에 따른 목록 조회
E13: 08 | F13: [검색조건] 조회일자 : [1달] 버튼 조회 | H13: 조건에 따른 목록 조회
E14: 09 | F14: [검색조건] 조회일자 : [2달] 버튼 조회 | H14: 조건에 따른 목록 조회
E15: 10 | F15: [검색조건] 수 · 출입 : 수입 선택 후 검색조건별 조회 | H15: 조건에 따른 목록 조회
E16: 11 | F16: 목록 선택하여 지도에 운송체 아이콘 표출 | H16: 지도에 아이콘 표시
E17: 12 | F17: 지도의 운송체 아이콘 선택하여 팝업 노출 | H17: -운송체 정보 노출 -출발지~도착지 정보 노출 -최종 정보 수집일시 정보 노출 -[상세정보] 버튼 선택하여 운송체 세부 정보 노출 -[TRACKING] 버튼 선택하여 [화물추적 (Tab)]으로 이동
E18: 13 | F18: 검색된 목록의 [화물추적] 버튼 선택 | H18: [화물추적 (Tab)]으로 이동
D19: 화물추적 (Tab) | E19: 14 | F19: (수 · 출입 : 수입이 선택되어 있음) 선사/포워더 : 수동 입력 후 조회 | H19: 조건에 따른 목록 조회
E20: 15 | F20: [검색조건] 선사/포워더 : [LIST] 버튼 조회 | H20: 선사/포워더 조회 팝업 노출
E21: 16 | F21: [선사/포워더 팝업창] 조회 -코드값 입력하여 조회 -조회된 목록 선택하여 검색옵션에 자동입력 | H21: 조건에 따른 목록 조회
E22: 17 | F22: [검색조건] 검색조건 : [LIST] 버튼 조회 (BL조회) | H22: B/L 조회 팝업 노출
E23: 18 | F23: [B/L 조회 팝업창] 조회 -조회일자 : 시작일~종료일 선택 조회 -[2주] 버튼 조회 -[1달] 버튼 조회 -[2달] 버튼 조회 -수 · 출입 옵션 선택 후 검색조건 선택 조회 -B/L 입력하여 조회 -조회된 목록 선택하여 검색옵션에 자동입력 | H23: 조건에 따른 목록 조회
E24: 19 | F24: [Event Tracking] -선박운송 | H24: 기항지별 출발/도착 시간 노출
E25: 20 | F25: [Event Tracking] -항공기운송 | H25: 출발/도착 시간 노출
E26: 21 | F26: [Event Tracking] -내륙운송(컨테이너) | H26: 컨테이너 번호 노출 -이벤트(출발(반출), 상차, 하차)별 시간 노출
E27: 22 | F27: [Event Tracking] -내육운송(화물) | H27: 이벤트(출발,하차)별 시간 노출
E28: 23 | F28: [Document Tracking] -DOCUMENT | H28: 수출입서류별 B/L 시간 노출
E29: 24 | F29: [Document Tracking] -수입화물진행정보 | H29: 세관서류별 시간 노출
D30: 운송자산 (Tab) | E30: 25 | F30: [검색조건] -운송유형, 운송상태, 검색조건 조회 | H30: 조건에 따른 목록 조회
E31: 26 | F31: [선박등록(직접) 팝업창]조회 -선박 조회 -신규 등록 | H31: -조건에 따른 목록 조회 -신규선박 등록
E32: 27 | F32: [입출항 팝업창]조회 -조회 -조회결과에서 체크하여 등록 | H32: -조건에 따른 목록 조회 -즐겨찾기 등록
E33: 28 | F33: 목록 선택하여 지도에 운송체 아이콘 표출 | H33: 지도에 아이콘 표시
E34: 29 | F34: 지도의 자산 아이콘 선택하여 팝업 노출 | H34: -항적 정보 노출 -[상세정보] 버튼 선택하여 운송체 세부 정보 노출
E35: 30 | F35: [운송자산 팝업창]의 [알람설정] -[알람설정] 버튼 선택하여 팝업창 노출 -알람설정 등록 | H35: -알람설정 등록 -조건에 따른 알람 발송
E36: 31 | F36: [운송자산 팝업창]의 [터미널정보] -[터미널정보] 버튼 선택하여 팝업창 노출 | H36: -터미널 정보 노출 -[하선장소] 선택하여 주소로 팝업창(지도) 노출 -선석배정현황 노출

Sheet 항공수출
A1: 시나리오명 | B1: 항공 수출 | F1: 시나리오 설명 | H1: 1) 항공 수출 업무 실데이터를 통한 화물추적 모니터링 테스트
A2: 업무흐름 | B2: 1) 항공 수출 업부에 따른 실 데이터를 입력하고 화물추적 모니터링화면에서 화물위치/화물추적/운송자산별로 데이터 추적을 진행한다. | F2: 테스트 결과 | H2: 구분 | I2: 테스트일자 | J2: 테스트 수 | K2: Pass 수 | L2: Fail 수 | M2: N/A | N2: 조치 수 | O2: 조치율 | P2: 테스트결과
H3: 통계 | I3: 44790 | J3: =COUNTA($F$6:$F$205) -> 31 | K3: =COUNTIF($J$6:$J$205,"P") -> 0 | L3: =COUNTIF($J$6:$J$205,"F") -> 0 | M3: =COUNTIF($J$6:$J$205,"N/A") -> 0 | N3: =COUNTA($O$6:$O$205) -> 0 | O3: =IFERROR(N3/L3,"-") -> - | P3: P
A4: 통합테스트 시나리오 | E4: 통합테스트 케이스 | J4: 테스트결과 | M4: 조치결과
A5: 사용자 | B5: 메뉴 | D5: 단위기능(화면 명) | E5: ID | F5: 테스트 케이스 | G5: 테스트 데이터 | H5: 예상결과 | I5: 사전조건 | J5: 테스트 결과 | K5: 결함내용/비고 | M5: 조치자 | N5: 조치예정일 | O5: 조치완료일 | P5: 조치내용/비고
A6: 무역업체(포워더) | B6: Shipping>수입B/L관리>항공AWB조회 | D6: 항공AWB조회 | E6: 01 | F6: [등록] 목록 화면에서 '신규'버튼 클릭. | H6: AWB등록 화면으로 이동 | I6: ID : FFRICS0001 (린코)
D7: 항공AWB조회 (Main TAB) | E7: 02 | F7: [등록] MAIN TAB 정보 등록 | G7: 수출입구분 업무유형 M AWB NO H AWB NO SHIPPIER CONSIGNEE NOTIFY AIR PORT OF DEPARTURE AIR PORT OF ARRIVAL TO / BY FLIGHT NO REQUEST NO DEPARTURE DATE ARRIVAL DATE REQUEST DATE | I7: 수출입구분 (수입) 업무유형(CONSOL) TO (출발공항코드) Ex) ICN BY (항공사 2 코드) Ex) OZ, KE
D8: 항공AWB조회 (Cargo TAB) | E8: 03 | F8: [등록] CARGO TAB 정보 등록 | G8: No of Piecces 포장종류 Gross Weight Exceuted on(Date) At(Place) | I8: Exceuted on(Date) (AWB 발행일자) At(Place) (AWB 발행장소)
D9: 항공AWB조회 (Other TAB) | E9: 04 | F9: [등록] OTHER TAB 정보 등록 | G9: MRN NO MSN HSN
E10: 05 | F10: [등록] TAB 정보를 등록 완료후 '저장'버튼 클릭. | H10: 목록화면으로 이동, 저장된 AWB등록건의 정보를 목록에서 표시 처리
A11: 무역업체(포워더) | B11: Cargo Tracking>My Cargo-Tracking>실시간모니터링 | D11: 화물위치 (Tab) | E11: 06 | F11: [검색조건] 조회일자 : [시작일]~[종료일] 조회 | H11: 조건에 따른 목록 조회 | I11: ID : FSARIR0001 (아리랑 국제물류)
E12: 07 | F12: [검색조건] 조회일자 : [2주] 버튼 조회 | H12: 조건에 따른 목록 조회
E13: 08 | F13: [검색조건] 조회일자 : [1달] 버튼 조회 | H13: 조건에 따른 목록 조회
E14: 09 | F14: [검색조건] 조회일자 : [2달] 버튼 조회 | H14: 조건에 따른 목록 조회
E15: 10 | F15: [검색조건] 수 · 출입 : 수출 선택 후 검색조건별 조회 | H15: 조건에 따른 목록 조회
E16: 11 | F16: 목록 선택하여 지도에 운송체 아이콘 표출 | H16: 지도에 아이콘 표시
E17: 12 | F17: 지도의 운송체 아이콘 선택하여 팝업 노출 | H17: -운송체 정보 노출 -출발지~도착지 정보 노출 -최종 정보 수집일시 정보 노출 -[상세정보] 버튼 선택하여 운송체 세부 정보 노출 -[TRACKING] 버튼 선택하여 [화물추적 (Tab)]으로 이동
E18: 13 | F18: 검색된 목록의 [화물추적] 버튼 선택 | H18: [화물추적 (Tab)]으로 이동
D19: 화물추적 (Tab) | E19: 14 | F19: (수 · 출입 : 수출이 선택되어 있음) 선사/포워더 : 수동 입력 후 조회 | H19: 조건에 따른 목록 조회
E20: 15 | F20: [검색조건] 선사/포워더 : [LIST] 버튼 조회 | H20: 선사/포워더 조회 팝업 노출
E21: 16 | F21: [선사/포워더 팝업창] 조회 -코드값 입력하여 조회 -조회된 목록 선택하여 검색옵션에 자동입력 | H21: 조건에 따른 목록 조회
E22: 17 | F22: [검색조건] 검색조건 : [LIST] 버튼 조회 (BL조회) | H22: B/L 조회 팝업 노출
E23: 18 | F23: [B/L 조회 팝업창] 조회 -조회일자 : 시작일~종료일 선택 조회 -[2주] 버튼 조회 -[1달] 버튼 조회 -[2달] 버튼 조회 -수 · 출입 옵션 선택 후 검색조건 선택 조회 -B/L 입력하여 조회 -조회된 목록 선택하여 검색옵션에 자동입력 | H23: 조건에 따른 목록 조회
E24: 19 | F24: [Event Tracking] -선박운송 | H24: 기항지별 출발/도착 시간 노출
E25: 20 | F25: [Event Tracking] -항공기운송 | H25: 출발/도착 시간 노출
E26: 21 | F26: [Event Tracking] -내륙운송(컨테이너) | H26: 컨테이너 번호 노출 -이벤트(출발(반출), 상차, 하차)별 시간 노출
E27: 22 | F27: [Event Tracking] -내육운송(화물) | H27: 이벤트(출발,하차)별 시간 노출
E28: 23 | F28: [Document Tracking] -DOCUMENT | H28: 수출입서류별 B/L 시간 노출
E29: 24 | F29: [Document Tracking] -수출화물진행정보 | H29: 세관서류별 시간 노출
D30: 운송자산 (Tab) | E30: 25 | F30: [검색조건] -운송유형, 운송상태, 검색조건 조회 | H30: 조건에 따른 목록 조회
E31: 26 | F31: [선박등록(직접) 팝업창]조회 -선박 조회 -신규 등록 | H31: -조건에 따른 목록 조회 -신규선박 등록
E32: 27 | F32: [입출항 팝업창]조회 -조회 -조회결과에서 체크하여 등록 | H32: -조건에 따른 목록 조회 -즐겨찾기 등록
E33: 28 | F33: 목록 선택하여 지도에 운송체 아이콘 표출 | H33: 지도에 아이콘 표시
E34: 29 | F34: 지도의 자산 아이콘 선택하여 팝업 노출 | H34: -항적 정보 노출 -[상세정보] 버튼 선택하여 운송체 세부 정보 노출
E35: 30 | F35: [운송자산 팝업창]의 [알람설정] -[알람설정] 버튼 선택하여 팝업창 노출 -알람설정 등록 | H35: -알람설정 등록 -조건에 따른 알람 발송
E36: 31 | F36: [운송자산 팝업창]의 [터미널정보] -[터미널정보] 버튼 선택하여 팝업창 노출 | H36: -터미널 정보 노출 -[하선장소] 선택하여 주소로 팝업창(지도) 노출 -선석배정현황 노출
